<?xml version="1.0" ?>
<!-- =================================================================================== -->
<!-- |    This document was autogenerated by xacro from BMW.urdf.xacro                 | -->
<!-- |    EDITING THIS FILE BY HAND IS NOT RECOMMENDED                                 | -->
<!-- =================================================================================== -->
<robot name="BMW_Car">
  <material name="blue">
    <color rgba="0 0.2 0.9 1"/>
  </material>
  <material name="gray">
    <color rgba="0.1 0.1 0.1 1"/>
  </material>
  <material name="darkBlue">
    <color rgba="0 0 0.1 1"/>
  </material>
  <link name="dummy_link"/>
  <!-- Chassis -->
  <link name="chassis">
    <visual>
      <geometry>
        <box size="0.6 0.7 0.1"/>
      </geometry>
      <origin rpy="0 0 1.57" xyz="0 0 0"/>
      <material name="darkBlue"/>
    </visual>
    <collision>
      <geometry>
        <box size="0.6 0.7 0.1"/>
      </geometry>
      <origin rpy="0 0 1.57" xyz="0 0 0"/>
    </collision>
    <inertial>
      <origin rpy="0 0 1.57" xyz="0 0 0"/>
      <mass value="0.1"/>
      <inertia ixx="0.004166666666666666" ixy="0.0" ixz="0.0" iyy="0.0030833333333333333" iyz="0.0" izz="0.007083333333333332"/>
    </inertial>
  </link>
  <joint name="chassis_joint" type="fixed">
    <parent link="dummy_link"/>
    <child link="chassis"/>
    <origin xyz="0 0 0"/>
  </joint>
  <gazebo reference="chassis">
    <material>Gazebo/DarkMagentaTransparent</material>
  </gazebo>
  <!-- Front Left Wheel -->
  <link name="LB_wheel">
    <visual>
      <geometry>
        <cylinder length="0.07" radius="0.2"/>
      </geometry>
      <material name="gray"/>
    </visual>
    <collision>
      <geometry>
        <sphere radius="0.2"/>
      </geometry>
    </collision>
    <inertial>
      <origin rpy="0 0 0" xyz="0 0 0"/>
      <mass value="0.05"/>
      <inertia ixx="0.0005204166666666667" ixy="0.0" ixz="0.0" iyy="0.0005204166666666667" iyz="0.0" izz="0.0010000000000000002"/>
    </inertial>
  </link>
  <joint name="LB_wheel_joint" type="continuous">
    <parent link="chassis"/>
    <child link="LB_wheel"/>
    <origin rpy="0 1.57 -1.57" xyz="-0.333 0.333 0"/>
    <axis xyz="0 0 -1"/>
    <!-- 조인트 물리 속성 추가 -->
    <limit effort="10" lower="-3.14" upper="3.14" velocity="100"/>
    <dynamics damping="0.1" friction="0.1"/>
    <safety_controller k_velocity="1.0" soft_lower_limit="-100" soft_upper_limit="100"/>
  </joint>
  <gazebo reference="LB_wheel">
    <material>Gazebo/Black</material>
    <mu1 value="0.2"/>
    <mu2 value="0.2"/>
  </gazebo>
  <!-- Back Left wheel -->
  <link name="RB_wheel">
    <visual>
      <geometry>
        <cylinder length="0.07" radius="0.2"/>
      </geometry>
      <material name="gray"/>
    </visual>
    <collision>
      <geometry>
        <sphere radius="0.2"/>
      </geometry>
    </collision>
    <inertial>
      <origin rpy="0 0 0" xyz="0 0 0"/>
      <mass value="0.05"/>
      <inertia ixx="0.0005204166666666667" ixy="0.0" ixz="0.0" iyy="0.0005204166666666667" iyz="0.0" izz="0.0010000000000000002"/>
    </inertial>
  </link>
  <joint name="RB_wheel_joint" type="continuous">
    <parent link="chassis"/>
    <child link="RB_wheel"/>
    <origin rpy="0 1.57 -1.57" xyz="-0.333 -0.333 0"/>
    <axis xyz="0 0 -1"/>
    <!-- 조인트 물리 속성 추가 -->
    <limit effort="10" lower="-3.14" upper="3.14" velocity="100"/>
    <dynamics damping="0.1" friction="0.1"/>
    <safety_controller k_velocity="1.0" soft_lower_limit="-100" soft_upper_limit="100"/>
  </joint>
  <gazebo reference="RB_wheel">
    <material>Gazebo/Black</material>
    <mu1 value="0.2"/>
    <mu2 value="0.2"/>
  </gazebo>
  <!-- Front Right Wheel -->
  <link name="LF_wheel">
    <visual>
      <geometry>
        <cylinder length="0.07" radius="0.2"/>
      </geometry>
      <material name="gray"/>
    </visual>
    <collision>
      <geometry>
        <sphere radius="0.2"/>
      </geometry>
    </collision>
    <inertial>
      <origin rpy="0 0 0" xyz="0 0 0"/>
      <mass value="0.05"/>
      <inertia ixx="0.0005204166666666667" ixy="0.0" ixz="0.0" iyy="0.0005204166666666667" iyz="0.0" izz="0.0010000000000000002"/>
    </inertial>
  </link>
  <joint name="LF_wheel_joint" type="continuous">
    <parent link="chassis"/>
    <child link="LF_wheel"/>
    <origin rpy="0 1.57 -1.57" xyz="0.333 0.333 0"/>
    <axis xyz="0 0 -1"/>
    <!-- 조인트 물리 속성 추가 -->
    <limit effort="10" lower="-3.14" upper="3.14" velocity="100"/>
    <dynamics damping="0.1" friction="0.1"/>
    <safety_controller k_velocity="1.0" soft_lower_limit="-100" soft_upper_limit="100"/>
  </joint>
  <gazebo reference="LF_wheel">
    <material>Gazebo/Black</material>
    <mu1 value="0.2"/>
    <mu2 value="0.2"/>
  </gazebo>
  <!-- Back Right Wheel -->
  <link name="RF_wheel">
    <visual>
      <geometry>
        <cylinder length="0.07" radius="0.2"/>
      </geometry>
      <material name="gray"/>
    </visual>
    <collision>
      <geometry>
        <sphere radius="0.2"/>
      </geometry>
    </collision>
    <inertial>
      <origin rpy="0 0 0" xyz="0 0 0"/>
      <mass value="0.05"/>
      <inertia ixx="0.0005204166666666667" ixy="0.0" ixz="0.0" iyy="0.0005204166666666667" iyz="0.0" izz="0.0010000000000000002"/>
    </inertial>
  </link>
  <joint name="RF_wheel_joint" type="continuous">
    <parent link="chassis"/>
    <child link="RF_wheel"/>
    <origin rpy="0 1.57 -1.57" xyz="0.333 -0.333 0"/>
    <axis xyz="0 0 -1"/>
    <!-- 조인트 물리 속성 추가 -->
    <limit effort="10" lower="-3.14" upper="3.14" velocity="100"/>
    <dynamics damping="0.1" friction="0.1"/>
    <safety_controller k_velocity="1.0" soft_lower_limit="-100" soft_upper_limit="100"/>
  </joint>
  <gazebo reference="RF_wheel">
    <material>Gazebo/Black</material>
    <mu1 value="0.2"/>
    <mu2 value="0.2"/>
  </gazebo>
  <!-- Transmission: ros2_control이 각 조인트를 velocity 인터페이스로 제어할 수 있게 매핑 -->
  <transmission name="LF_wheel_transmission">
    <type>transmission_interface/SimpleTransmission</type>
    <joint name="LF_wheel_joint">
      <hardwareInterface>hardware_interface/VelocityJointInterface</hardwareInterface>
    </joint>
    <actuator name="LF_wheel_motor">
      <hardwareInterface>hardware_interface/VelocityJointInterface</hardwareInterface>
      <mechanicalReduction>1</mechanicalReduction>
    </actuator>
  </transmission>
  <transmission name="RF_wheel_transmission">
    <type>transmission_interface/SimpleTransmission</type>
    <joint name="RF_wheel_joint">
      <hardwareInterface>hardware_interface/VelocityJointInterface</hardwareInterface>
    </joint>
    <actuator name="RF_wheel_motor">
      <hardwareInterface>hardware_interface/VelocityJointInterface</hardwareInterface>
      <mechanicalReduction>1</mechanicalReduction>
    </actuator>
  </transmission>
  <transmission name="LB_wheel_transmission">
    <type>transmission_interface/SimpleTransmission</type>
    <joint name="LB_wheel_joint">
      <hardwareInterface>hardware_interface/VelocityJointInterface</hardwareInterface>
    </joint>
    <actuator name="LB_wheel_motor">
      <hardwareInterface>hardware_interface/VelocityJointInterface</hardwareInterface>
      <mechanicalReduction>1</mechanicalReduction>
    </actuator>
  </transmission>
  <transmission name="RB_wheel_transmission">
    <type>transmission_interface/SimpleTransmission</type>
    <joint name="RB_wheel_joint">
      <hardwareInterface>hardware_interface/VelocityJointInterface</hardwareInterface>
    </joint>
    <actuator name="RB_wheel_motor">
      <hardwareInterface>hardware_interface/VelocityJointInterface</hardwareInterface>
      <mechanicalReduction>1</mechanicalReduction>
    </actuator>
  </transmission>
  <!-- Lidar -->
  <link name="lidar">
    <visual>
      <geometry>
        <cylinder length="0.25" radius="0.15"/>
      </geometry>
      <origin rpy="0 0 0" xyz="-0.16 0 0.1"/>
      <material name="blue"/>
    </visual>
    <collision>
      <geometry>
        <cylinder length="0.25" radius="0.15"/>
      </geometry>
      <origin rpy="0 0 0" xyz="-0.16 0 0.1"/>
    </collision>
    <inertial>
      <origin rpy="0 0 0" xyz="-0.16 0 0.1"/>
      <mass value="0.1"/>
      <inertia ixx="0.0010833333333333333" ixy="0.0" ixz="0.0" iyy="0.0010833333333333333" iyz="0.0" izz="0.001125"/>
    </inertial>
  </link>
  <joint name="lidar_joint" type="fixed">
    <parent link="chassis"/>
    <child link="lidar"/>
    <origin rpy="0 0 0" xyz="0 0 0"/>
  </joint>
  <gazebo reference="lidar">
    <material>Gazebo/Indigo</material>
  </gazebo>
  <!-- Camera-->
  <link name="camera">
    <visual>
      <geometry>
        <box size="0.15 0.15 0.08"/>
      </geometry>
      <origin rpy="0 0 0" xyz="0.2 0 0.05"/>
      <material name="blue"/>
    </visual>
    <collision>
      <geometry>
        <box size="0.15 0.15 0.08"/>
      </geometry>
      <origin rpy="0 0 0" xyz="0.2 0 0.05"/>
    </collision>
    <inertial>
      <origin rpy="0 0 0" xyz="0 0 0"/>
      <mass value="0.05"/>
      <inertia ixx="0.00012041666666666666" ixy="0.0" ixz="0.0" iyy="0.00012041666666666666" iyz="0.0" izz="0.0001875"/>
    </inertial>
  </link>
  <joint name="camera_joint" type="fixed">
    <parent link="chassis"/>
    <child link="camera"/>
    <origin rpy="0 0 0" xyz="0.2 0 0.05"/>
  </joint>
  <gazebo reference="camera">
    <material>Gazebo/Blue</material>
  </gazebo>
  <hardware>
    <plugin>gazebo_ros2_control/GazeboSystem</plugin>
  </hardware>
  <joint name="LF_wheel_joint">
    <command_interface name="velocity"/>
    <state_interface name="velocity"/>
    <state_interface name="position"/>
  </joint>
  <joint name="RF_wheel_joint">
    <command_interface name="velocity"/>
    <state_interface name="velocity"/>
    <state_interface name="position"/>
  </joint>
  <joint name="LB_wheel_joint">
    <command_interface name="velocity"/>
    <state_interface name="velocity"/>
    <state_interface name="position"/>
  </joint>
  <joint name="RB_wheel_joint">
    <command_interface name="velocity"/>
    <state_interface name="velocity"/>
    <state_interface name="position"/>
  </joint>
  <gazebo>
    <plugin filename="libgazebo_ros2_control.so" name="gazebo_ros2_control">
      <robotNamespace>/</robotNamespace>
      <robotParam>robot_description</robotParam>
      <robotParamNode>robot_state_publisher</robotParamNode>
      <!-- 컨트롤러 파라미터 파일 경로 지정은 런치 파일에서 할 수도 있음 -->
    </plugin>
  </gazebo>
  <!-- 각각의 내용이 독립 태그라면 아래처럼 직접 삽입 -->
  <ros2_control name="GazeboSystem" type="system">
    <!-- ros2_control 내부 내용 -->
  </ros2_control>
  <gazebo>
    <plugin filename="libgazebo_ros2_control.so" name="gazebo_ros2_control">
      <!-- gazebo_control 내부 내용 -->
    </plugin>
  </gazebo>
</robot>
