<?xml version="1.0" ?>
<!-- =================================================================================== -->
<!-- |    This document was autogenerated by xacro from /home/kkit/programming/ROS2/Ros_ws_book/src/slampibot_gazebo/myCar/real_BMW_core.xacro | -->
<!-- |    EDITING THIS FILE BY HAND IS NOT RECOMMENDED                                 | -->
<!-- =================================================================================== -->
<robot name="BMW_Car">
  <!-- This file describes the real, physical properties of the robot. -->
  <!-- All simulation-specific tags (<gazebo>, <transmission>) have been removed. -->
  <!-- All dimensions are in meters. -->
  <!-- Adjusted mass for the chassis -->
  <!-- Materials for RViz visualization -->
  <material name="blue">
    <color rgba="0 0.2 0.9 1"/>
  </material>
  <material name="gray">
    <color rgba="0.1 0.1 0.1 1"/>
  </material>
  <material name="darkBlue">
    <color rgba="0 0 0.1 1"/>
  </material>
  <!-- Base link for the robot model -->
  <link name="dummy_link"/>
  <!-- Chassis -->
  <link name="chassis">
    <visual>
      <geometry>
        <!-- Real dimensions: 0.257m x 0.150m x 0.002m -->
        <box size="0.257 0.150 0.002"/>
      </geometry>
      <material name="darkBlue"/>
    </visual>
    <collision>
      <geometry>
        <box size="0.257 0.150 0.002"/>
      </geometry>
    </collision>
    <inertial>
      <origin rpy="0 0 0" xyz="0 0 0"/>
      <mass value="0.5"/>
      <inertia ixx="0.0009376666666666666" ixy="0.0" ixz="0.0" iyy="0.002752208333333333" iyz="0.0" izz="0.003689541666666666"/>
    </inertial>
  </link>
  <joint name="chassis_joint" type="fixed">
    <parent link="dummy_link"/>
    <child link="chassis"/>
    <origin xyz="0 0 0.033"/>
    <!-- Place chassis so wheels are on the ground (z=radius) -->
  </joint>
  <!-- chassis_y/2 + wheel_length/2 -->
  <!-- Front Left Wheel -->
  <link name="LF_wheel">
    <visual>
      <geometry>
        <cylinder length="0.017" radius="0.033"/>
      </geometry>
      <origin rpy="1.5707 0 0" xyz="0 0 0"/>
      <material name="gray"/>
    </visual>
    <collision>
      <geometry>
        <cylinder length="0.017" radius="0.033"/>
      </geometry>
      <origin rpy="1.5707 0 0" xyz="0 0 0"/>
    </collision>
    <inertial>
      <origin rpy="1.5707 0 0" xyz="0 0 0"/>
      <mass value="0.05"/>
      <inertia ixx="1.4816666666666668e-05" ixy="0.0" ixz="0.0" iyy="1.4816666666666668e-05" iyz="0.0" izz="2.7225000000000004e-05"/>
    </inertial>
  </link>
  <joint name="LF_wheel_joint" type="continuous">
    <parent link="chassis"/>
    <child link="LF_wheel"/>
    <origin rpy="0 0 0" xyz="0.06425 0.0835 0"/>
    <axis xyz="0 1 0"/>
  </joint>
  <!-- Back Left wheel -->
  <link name="LB_wheel">
    <visual>
      <geometry>
        <cylinder length="0.017" radius="0.033"/>
      </geometry>
      <origin rpy="1.5707 0 0" xyz="0 0 0"/>
      <material name="gray"/>
    </visual>
    <collision>
      <geometry>
        <cylinder length="0.017" radius="0.033"/>
      </geometry>
      <origin rpy="1.5707 0 0" xyz="0 0 0"/>
    </collision>
    <inertial>
      <origin rpy="1.5707 0 0" xyz="0 0 0"/>
      <mass value="0.05"/>
      <inertia ixx="1.4816666666666668e-05" ixy="0.0" ixz="0.0" iyy="1.4816666666666668e-05" iyz="0.0" izz="2.7225000000000004e-05"/>
    </inertial>
  </link>
  <joint name="LB_wheel_joint" type="continuous">
    <parent link="chassis"/>
    <child link="LB_wheel"/>
    <origin rpy="0 0 0" xyz="-0.06425 0.0835 0"/>
    <axis xyz="0 1 0"/>
  </joint>
  <!-- Front Right Wheel -->
  <link name="RF_wheel">
    <visual>
      <geometry>
        <cylinder length="0.017" radius="0.033"/>
      </geometry>
      <origin rpy="1.5707 0 0" xyz="0 0 0"/>
      <material name="gray"/>
    </visual>
    <collision>
      <geometry>
        <cylinder length="0.017" radius="0.033"/>
      </geometry>
      <origin rpy="1.5707 0 0" xyz="0 0 0"/>
    </collision>
    <inertial>
      <origin rpy="1.5707 0 0" xyz="0 0 0"/>
      <mass value="0.05"/>
      <inertia ixx="1.4816666666666668e-05" ixy="0.0" ixz="0.0" iyy="1.4816666666666668e-05" iyz="0.0" izz="2.7225000000000004e-05"/>
    </inertial>
  </link>
  <joint name="RF_wheel_joint" type="continuous">
    <parent link="chassis"/>
    <child link="RF_wheel"/>
    <origin rpy="0 0 0" xyz="0.06425 -0.0835 0"/>
    <axis xyz="0 1 0"/>
  </joint>
  <!-- Back Right Wheel -->
  <link name="RB_wheel">
    <visual>
      <geometry>
        <cylinder length="0.017" radius="0.033"/>
      </geometry>
      <origin rpy="1.5707 0 0" xyz="0 0 0"/>
      <material name="gray"/>
    </visual>
    <collision>
      <geometry>
        <cylinder length="0.017" radius="0.033"/>
      </geometry>
      <origin rpy="1.5707 0 0" xyz="0 0 0"/>
    </collision>
    <inertial>
      <origin rpy="1.5707 0 0" xyz="0 0 0"/>
      <mass value="0.05"/>
      <inertia ixx="1.4816666666666668e-05" ixy="0.0" ixz="0.0" iyy="1.4816666666666668e-05" iyz="0.0" izz="2.7225000000000004e-05"/>
    </inertial>
  </link>
  <joint name="RB_wheel_joint" type="continuous">
    <parent link="chassis"/>
    <child link="RB_wheel"/>
    <origin rpy="0 0 0" xyz="-0.06425 -0.0835 0"/>
    <axis xyz="0 1 0"/>
  </joint>
  <!-- Lidar Sensor -->
  <link name="lidar_link">
    <visual>
      <geometry>
        <cylinder length="0.04" radius="0.05"/>
      </geometry>
      <material name="blue"/>
    </visual>
    <collision>
      <geometry>
        <cylinder length="0.04" radius="0.05"/>
      </geometry>
    </collision>
    <inertial>
      <origin rpy="0 0 0" xyz="0 0 0"/>
      <mass value="0.1"/>
      <inertia ixx="7.583333333333335e-05" ixy="0.0" ixz="0.0" iyy="7.583333333333335e-05" iyz="0.0" izz="0.00012500000000000003"/>
    </inertial>
  </link>
  <joint name="lidar_joint" type="fixed">
    <parent link="chassis"/>
    <child link="lidar_link"/>
    <origin rpy="0 0 0" xyz="0.10 0 0.02"/>
    <!-- Adjust position as needed -->
  </joint>
  <!-- Camera Sensor -->
  <link name="camera_link">
    <visual>
      <geometry>
        <box size="0.03 0.05 0.03"/>
      </geometry>
      <material name="blue"/>
    </visual>
    <collision>
      <geometry>
        <box size="0.03 0.05 0.03"/>
      </geometry>
    </collision>
    <inertial>
      <origin rpy="0 0 0" xyz="0 0 0"/>
      <mass value="0.01"/>
      <inertia ixx="2.8333333333333335e-06" ixy="0.0" ixz="0.0" iyy="1.4999999999999998e-06" iyz="0.0" izz="2.8333333333333335e-06"/>
    </inertial>
  </link>
  <joint name="camera_joint" type="fixed">
    <parent link="chassis"/>
    <child link="camera_link"/>
    <origin rpy="0 0 0" xyz="0.12 0 0.01"/>
    <!-- Adjust position as needed -->
  </joint>
</robot>
